[2024-03-03T00:56:59.844+0530] {taskinstance.py:1979} INFO - Dependencies all met for dep_context=non-requeueable deps ti=<TaskInstance: weather_data_pipeline.compute_averages manual__2024-03-02T19:24:10.303999+00:00 [queued]>
[2024-03-03T00:56:59.845+0530] {taskinstance.py:1979} INFO - Dependencies all met for dep_context=requeueable deps ti=<TaskInstance: weather_data_pipeline.compute_averages manual__2024-03-02T19:24:10.303999+00:00 [queued]>
[2024-03-03T00:56:59.846+0530] {taskinstance.py:2193} INFO - Starting attempt 2 of 3
[2024-03-03T00:56:59.849+0530] {taskinstance.py:2214} INFO - Executing <Task(PythonOperator): compute_averages> on 2024-03-02 19:24:10.303999+00:00
[2024-03-03T00:56:59.853+0530] {standard_task_runner.py:60} INFO - Started process 29031 to run task
[2024-03-03T00:56:59.856+0530] {standard_task_runner.py:87} INFO - Running: ['airflow', 'tasks', 'run', 'weather_data_pipeline', 'compute_averages', 'manual__2024-03-02T19:24:10.303999+00:00', '--job-id', '288', '--raw', '--subdir', 'DAGS_FOLDER/Data_analysis.py', '--cfg-path', '/var/folders/th/tnjyp6yd1cj78nysn5t4jl6h0000gn/T/tmpei9aj0ro']
[2024-03-03T00:56:59.856+0530] {standard_task_runner.py:88} INFO - Job 288: Subtask compute_averages
[2024-03-03T00:56:59.873+0530] {task_command.py:423} INFO - Running <TaskInstance: weather_data_pipeline.compute_averages manual__2024-03-02T19:24:10.303999+00:00 [running]> on host aniks-macbook-air.local
[2024-03-03T00:56:59.898+0530] {taskinstance.py:2510} INFO - Exporting env vars: AIRFLOW_CTX_DAG_OWNER='airflow' AIRFLOW_CTX_DAG_ID='weather_data_pipeline' AIRFLOW_CTX_TASK_ID='compute_averages' AIRFLOW_CTX_EXECUTION_DATE='2024-03-02T19:24:10.303999+00:00' AIRFLOW_CTX_TRY_NUMBER='2' AIRFLOW_CTX_DAG_RUN_ID='manual__2024-03-02T19:24:10.303999+00:00'
[2024-03-03T00:56:59.898+0530] {taskinstance.py:2728} ERROR - Task failed with exception
Traceback (most recent call last):
  File "/Users/anikbhowmick/Python/Big_Data_Assignment/A02/airflow_env/lib/python3.11/site-packages/airflow/models/taskinstance.py", line 444, in _execute_task
    result = _execute_callable(context=context, **execute_callable_kwargs)
             ^^^^^^^^^^^^^^^^^^^^^^^^^^^^^^^^^^^^^^^^^^^^^^^^^^^^^^^^^^^^^
  File "/Users/anikbhowmick/Python/Big_Data_Assignment/A02/airflow_env/lib/python3.11/site-packages/airflow/models/taskinstance.py", line 414, in _execute_callable
    return execute_callable(context=context, **execute_callable_kwargs)
           ^^^^^^^^^^^^^^^^^^^^^^^^^^^^^^^^^^^^^^^^^^^^^^^^^^^^^^^^^^^^
  File "/Users/anikbhowmick/Python/Big_Data_Assignment/A02/airflow_env/lib/python3.11/site-packages/airflow/operators/python.py", line 200, in execute
    return_value = self.execute_callable()
                   ^^^^^^^^^^^^^^^^^^^^^^^
  File "/Users/anikbhowmick/Python/Big_Data_Assignment/A02/airflow_env/lib/python3.11/site-packages/airflow/operators/python.py", line 217, in execute_callable
    return self.python_callable(*self.op_args, **self.op_kwargs)
           ^^^^^^^^^^^^^^^^^^^^^^^^^^^^^^^^^^^^^^^^^^^^^^^^^^^^^
TypeError: compute_monthly_averages() missing 1 required positional argument: 'data'
[2024-03-03T00:56:59.901+0530] {taskinstance.py:1149} INFO - Marking task as UP_FOR_RETRY. dag_id=weather_data_pipeline, task_id=compute_averages, execution_date=20240302T192410, start_date=20240302T192659, end_date=20240302T192659
[2024-03-03T00:56:59.904+0530] {standard_task_runner.py:107} ERROR - Failed to execute job 288 for task compute_averages (compute_monthly_averages() missing 1 required positional argument: 'data'; 29031)
[2024-03-03T00:56:59.917+0530] {local_task_job_runner.py:234} INFO - Task exited with return code 1
[2024-03-03T00:56:59.923+0530] {taskinstance.py:3309} INFO - 0 downstream tasks scheduled from follow-on schedule check
