[2024-03-03T01:19:53.531+0530] {taskinstance.py:1979} INFO - Dependencies all met for dep_context=non-requeueable deps ti=<TaskInstance: weather_data_pipeline.compute_averages manual__2024-03-02T19:24:10.303999+00:00 [queued]>
[2024-03-03T01:19:53.533+0530] {taskinstance.py:1979} INFO - Dependencies all met for dep_context=requeueable deps ti=<TaskInstance: weather_data_pipeline.compute_averages manual__2024-03-02T19:24:10.303999+00:00 [queued]>
[2024-03-03T01:19:53.533+0530] {taskinstance.py:2193} INFO - Starting attempt 13 of 13
[2024-03-03T01:19:53.537+0530] {taskinstance.py:2214} INFO - Executing <Task(PythonOperator): compute_averages> on 2024-03-02 19:24:10.303999+00:00
[2024-03-03T01:19:53.540+0530] {standard_task_runner.py:60} INFO - Started process 30968 to run task
[2024-03-03T01:19:53.543+0530] {standard_task_runner.py:87} INFO - Running: ['airflow', 'tasks', 'run', 'weather_data_pipeline', 'compute_averages', 'manual__2024-03-02T19:24:10.303999+00:00', '--job-id', '323', '--raw', '--subdir', 'DAGS_FOLDER/Data_analysis.py', '--cfg-path', '/var/folders/th/tnjyp6yd1cj78nysn5t4jl6h0000gn/T/tmppkf3ktk9']
[2024-03-03T01:19:53.544+0530] {standard_task_runner.py:88} INFO - Job 323: Subtask compute_averages
[2024-03-03T01:19:53.563+0530] {task_command.py:423} INFO - Running <TaskInstance: weather_data_pipeline.compute_averages manual__2024-03-02T19:24:10.303999+00:00 [running]> on host aniks-macbook-air.local
[2024-03-03T01:19:53.582+0530] {taskinstance.py:2510} INFO - Exporting env vars: AIRFLOW_CTX_DAG_OWNER='airflow' AIRFLOW_CTX_DAG_ID='weather_data_pipeline' AIRFLOW_CTX_TASK_ID='compute_averages' AIRFLOW_CTX_EXECUTION_DATE='2024-03-02T19:24:10.303999+00:00' AIRFLOW_CTX_TRY_NUMBER='13' AIRFLOW_CTX_DAG_RUN_ID='manual__2024-03-02T19:24:10.303999+00:00'
[2024-03-03T01:19:53.584+0530] {taskinstance.py:2728} ERROR - Task failed with exception
Traceback (most recent call last):
  File "/Users/anikbhowmick/Python/Big_Data_Assignment/A02/airflow_env/lib/python3.11/site-packages/airflow/models/taskinstance.py", line 444, in _execute_task
    result = _execute_callable(context=context, **execute_callable_kwargs)
             ^^^^^^^^^^^^^^^^^^^^^^^^^^^^^^^^^^^^^^^^^^^^^^^^^^^^^^^^^^^^^
  File "/Users/anikbhowmick/Python/Big_Data_Assignment/A02/airflow_env/lib/python3.11/site-packages/airflow/models/taskinstance.py", line 414, in _execute_callable
    return execute_callable(context=context, **execute_callable_kwargs)
           ^^^^^^^^^^^^^^^^^^^^^^^^^^^^^^^^^^^^^^^^^^^^^^^^^^^^^^^^^^^^
  File "/Users/anikbhowmick/Python/Big_Data_Assignment/A02/airflow_env/lib/python3.11/site-packages/airflow/operators/python.py", line 200, in execute
    return_value = self.execute_callable()
                   ^^^^^^^^^^^^^^^^^^^^^^^
  File "/Users/anikbhowmick/Python/Big_Data_Assignment/A02/airflow_env/lib/python3.11/site-packages/airflow/operators/python.py", line 217, in execute_callable
    return self.python_callable(*self.op_args, **self.op_kwargs)
           ^^^^^^^^^^^^^^^^^^^^^^^^^^^^^^^^^^^^^^^^^^^^^^^^^^^^^
  File "/Users/anikbhowmick/Python/Big_Data_Assignment/A02/airflow_env/airflow/dags/Data_analysis.py", line 73, in compute_monthly_averages
    for data in data_list:
TypeError: '_InvalidUnpickledPCollection' object is not iterable
[2024-03-03T01:19:53.587+0530] {taskinstance.py:1149} INFO - Marking task as FAILED. dag_id=weather_data_pipeline, task_id=compute_averages, execution_date=20240302T192410, start_date=20240302T194953, end_date=20240302T194953
[2024-03-03T01:19:53.589+0530] {standard_task_runner.py:107} ERROR - Failed to execute job 323 for task compute_averages ('_InvalidUnpickledPCollection' object is not iterable; 30968)
[2024-03-03T01:19:53.604+0530] {local_task_job_runner.py:234} INFO - Task exited with return code 1
[2024-03-03T01:19:53.610+0530] {taskinstance.py:3309} INFO - 0 downstream tasks scheduled from follow-on schedule check
