[2024-03-03T00:12:26.238+0530] {taskinstance.py:1979} INFO - Dependencies all met for dep_context=non-requeueable deps ti=<TaskInstance: weather_data_pipeline.compute_averages manual__2024-03-02T18:11:44.984057+00:00 [queued]>
[2024-03-03T00:12:26.240+0530] {taskinstance.py:1979} INFO - Dependencies all met for dep_context=requeueable deps ti=<TaskInstance: weather_data_pipeline.compute_averages manual__2024-03-02T18:11:44.984057+00:00 [queued]>
[2024-03-03T00:12:26.240+0530] {taskinstance.py:2193} INFO - Starting attempt 5 of 6
[2024-03-03T00:12:26.243+0530] {taskinstance.py:2214} INFO - Executing <Task(PythonOperator): compute_averages> on 2024-03-02 18:11:44.984057+00:00
[2024-03-03T00:12:26.247+0530] {standard_task_runner.py:60} INFO - Started process 25971 to run task
[2024-03-03T00:12:26.249+0530] {standard_task_runner.py:87} INFO - Running: ['airflow', 'tasks', 'run', 'weather_data_pipeline', 'compute_averages', 'manual__2024-03-02T18:11:44.984057+00:00', '--job-id', '247', '--raw', '--subdir', 'DAGS_FOLDER/Data_analysis.py', '--cfg-path', '/var/folders/th/tnjyp6yd1cj78nysn5t4jl6h0000gn/T/tmp2pqcojj2']
[2024-03-03T00:12:26.250+0530] {standard_task_runner.py:88} INFO - Job 247: Subtask compute_averages
[2024-03-03T00:12:26.266+0530] {task_command.py:423} INFO - Running <TaskInstance: weather_data_pipeline.compute_averages manual__2024-03-02T18:11:44.984057+00:00 [running]> on host aniks-macbook-air.local
[2024-03-03T00:12:26.283+0530] {taskinstance.py:2510} INFO - Exporting env vars: AIRFLOW_CTX_DAG_OWNER='airflow' AIRFLOW_CTX_DAG_ID='weather_data_pipeline' AIRFLOW_CTX_TASK_ID='compute_averages' AIRFLOW_CTX_EXECUTION_DATE='2024-03-02T18:11:44.984057+00:00' AIRFLOW_CTX_TRY_NUMBER='5' AIRFLOW_CTX_DAG_RUN_ID='manual__2024-03-02T18:11:44.984057+00:00'
[2024-03-03T00:12:26.284+0530] {taskinstance.py:2728} ERROR - Task failed with exception
Traceback (most recent call last):
  File "/Users/anikbhowmick/Python/Big_Data_Assignment/A02/airflow_env/lib/python3.11/site-packages/airflow/models/taskinstance.py", line 444, in _execute_task
    result = _execute_callable(context=context, **execute_callable_kwargs)
             ^^^^^^^^^^^^^^^^^^^^^^^^^^^^^^^^^^^^^^^^^^^^^^^^^^^^^^^^^^^^^
  File "/Users/anikbhowmick/Python/Big_Data_Assignment/A02/airflow_env/lib/python3.11/site-packages/airflow/models/taskinstance.py", line 414, in _execute_callable
    return execute_callable(context=context, **execute_callable_kwargs)
           ^^^^^^^^^^^^^^^^^^^^^^^^^^^^^^^^^^^^^^^^^^^^^^^^^^^^^^^^^^^^
  File "/Users/anikbhowmick/Python/Big_Data_Assignment/A02/airflow_env/lib/python3.11/site-packages/airflow/operators/python.py", line 200, in execute
    return_value = self.execute_callable()
                   ^^^^^^^^^^^^^^^^^^^^^^^
  File "/Users/anikbhowmick/Python/Big_Data_Assignment/A02/airflow_env/lib/python3.11/site-packages/airflow/operators/python.py", line 217, in execute_callable
    return self.python_callable(*self.op_args, **self.op_kwargs)
           ^^^^^^^^^^^^^^^^^^^^^^^^^^^^^^^^^^^^^^^^^^^^^^^^^^^^^
TypeError: compute_monthly_averages() missing 1 required positional argument: 'data'
[2024-03-03T00:12:26.286+0530] {taskinstance.py:1149} INFO - Marking task as UP_FOR_RETRY. dag_id=weather_data_pipeline, task_id=compute_averages, execution_date=20240302T181144, start_date=20240302T184226, end_date=20240302T184226
[2024-03-03T00:12:26.289+0530] {standard_task_runner.py:107} ERROR - Failed to execute job 247 for task compute_averages (compute_monthly_averages() missing 1 required positional argument: 'data'; 25971)
[2024-03-03T00:12:26.311+0530] {local_task_job_runner.py:234} INFO - Task exited with return code 1
[2024-03-03T00:12:26.318+0530] {taskinstance.py:3309} INFO - 0 downstream tasks scheduled from follow-on schedule check
