[2024-03-02T23:46:52.429+0530] {taskinstance.py:1979} INFO - Dependencies all met for dep_context=non-requeueable deps ti=<TaskInstance: weather_data_pipeline.compute_averages manual__2024-03-02T18:11:44.984057+00:00 [queued]>
[2024-03-02T23:46:52.431+0530] {taskinstance.py:1979} INFO - Dependencies all met for dep_context=requeueable deps ti=<TaskInstance: weather_data_pipeline.compute_averages manual__2024-03-02T18:11:44.984057+00:00 [queued]>
[2024-03-02T23:46:52.431+0530] {taskinstance.py:2193} INFO - Starting attempt 2 of 2
[2024-03-02T23:46:52.434+0530] {taskinstance.py:2214} INFO - Executing <Task(PythonOperator): compute_averages> on 2024-03-02 18:11:44.984057+00:00
[2024-03-02T23:46:52.437+0530] {standard_task_runner.py:60} INFO - Started process 24462 to run task
[2024-03-02T23:46:52.440+0530] {standard_task_runner.py:87} INFO - Running: ['airflow', 'tasks', 'run', 'weather_data_pipeline', 'compute_averages', 'manual__2024-03-02T18:11:44.984057+00:00', '--job-id', '227', '--raw', '--subdir', 'DAGS_FOLDER/Data_analysis.py', '--cfg-path', '/var/folders/th/tnjyp6yd1cj78nysn5t4jl6h0000gn/T/tmpuhqr1njk']
[2024-03-02T23:46:52.441+0530] {standard_task_runner.py:88} INFO - Job 227: Subtask compute_averages
[2024-03-02T23:46:52.468+0530] {task_command.py:423} INFO - Running <TaskInstance: weather_data_pipeline.compute_averages manual__2024-03-02T18:11:44.984057+00:00 [running]> on host aniks-macbook-air.local
[2024-03-02T23:46:52.486+0530] {taskinstance.py:2510} INFO - Exporting env vars: AIRFLOW_CTX_DAG_OWNER='airflow' AIRFLOW_CTX_DAG_ID='weather_data_pipeline' AIRFLOW_CTX_TASK_ID='compute_averages' AIRFLOW_CTX_EXECUTION_DATE='2024-03-02T18:11:44.984057+00:00' AIRFLOW_CTX_TRY_NUMBER='2' AIRFLOW_CTX_DAG_RUN_ID='manual__2024-03-02T18:11:44.984057+00:00'
[2024-03-02T23:46:52.486+0530] {taskinstance.py:2728} ERROR - Task failed with exception
Traceback (most recent call last):
  File "/Users/anikbhowmick/Python/Big_Data_Assignment/A02/airflow_env/lib/python3.11/site-packages/airflow/models/taskinstance.py", line 444, in _execute_task
    result = _execute_callable(context=context, **execute_callable_kwargs)
             ^^^^^^^^^^^^^^^^^^^^^^^^^^^^^^^^^^^^^^^^^^^^^^^^^^^^^^^^^^^^^
  File "/Users/anikbhowmick/Python/Big_Data_Assignment/A02/airflow_env/lib/python3.11/site-packages/airflow/models/taskinstance.py", line 414, in _execute_callable
    return execute_callable(context=context, **execute_callable_kwargs)
           ^^^^^^^^^^^^^^^^^^^^^^^^^^^^^^^^^^^^^^^^^^^^^^^^^^^^^^^^^^^^
  File "/Users/anikbhowmick/Python/Big_Data_Assignment/A02/airflow_env/lib/python3.11/site-packages/airflow/operators/python.py", line 200, in execute
    return_value = self.execute_callable()
                   ^^^^^^^^^^^^^^^^^^^^^^^
  File "/Users/anikbhowmick/Python/Big_Data_Assignment/A02/airflow_env/lib/python3.11/site-packages/airflow/operators/python.py", line 217, in execute_callable
    return self.python_callable(*self.op_args, **self.op_kwargs)
           ^^^^^^^^^^^^^^^^^^^^^^^^^^^^^^^^^^^^^^^^^^^^^^^^^^^^^
TypeError: compute_monthly_averages() missing 1 required positional argument: 'data'
[2024-03-02T23:46:52.488+0530] {taskinstance.py:1149} INFO - Marking task as FAILED. dag_id=weather_data_pipeline, task_id=compute_averages, execution_date=20240302T181144, start_date=20240302T181652, end_date=20240302T181652
[2024-03-02T23:46:52.491+0530] {standard_task_runner.py:107} ERROR - Failed to execute job 227 for task compute_averages (compute_monthly_averages() missing 1 required positional argument: 'data'; 24462)
[2024-03-02T23:46:52.501+0530] {local_task_job_runner.py:234} INFO - Task exited with return code 1
[2024-03-02T23:46:52.507+0530] {taskinstance.py:3309} INFO - 0 downstream tasks scheduled from follow-on schedule check
