[2024-03-03T02:56:03.379+0530] {taskinstance.py:1979} INFO - Dependencies all met for dep_context=non-requeueable deps ti=<TaskInstance: weather_data_pipeline.compute_averages manual__2024-03-02T21:25:58.120094+00:00 [queued]>
[2024-03-03T02:56:03.381+0530] {taskinstance.py:1979} INFO - Dependencies all met for dep_context=requeueable deps ti=<TaskInstance: weather_data_pipeline.compute_averages manual__2024-03-02T21:25:58.120094+00:00 [queued]>
[2024-03-03T02:56:03.381+0530] {taskinstance.py:2193} INFO - Starting attempt 1 of 2
[2024-03-03T02:56:03.384+0530] {taskinstance.py:2214} INFO - Executing <Task(PythonOperator): compute_averages> on 2024-03-02 21:25:58.120094+00:00
[2024-03-03T02:56:03.388+0530] {standard_task_runner.py:60} INFO - Started process 36663 to run task
[2024-03-03T02:56:03.390+0530] {standard_task_runner.py:87} INFO - Running: ['airflow', 'tasks', 'run', 'weather_data_pipeline', 'compute_averages', 'manual__2024-03-02T21:25:58.120094+00:00', '--job-id', '396', '--raw', '--subdir', 'DAGS_FOLDER/Data_analysis.py', '--cfg-path', '/var/folders/th/tnjyp6yd1cj78nysn5t4jl6h0000gn/T/tmpsciw15fm']
[2024-03-03T02:56:03.391+0530] {standard_task_runner.py:88} INFO - Job 396: Subtask compute_averages
[2024-03-03T02:56:03.417+0530] {task_command.py:423} INFO - Running <TaskInstance: weather_data_pipeline.compute_averages manual__2024-03-02T21:25:58.120094+00:00 [running]> on host aniks-macbook-air.local
[2024-03-03T02:56:03.434+0530] {taskinstance.py:2510} INFO - Exporting env vars: AIRFLOW_CTX_DAG_OWNER='airflow' AIRFLOW_CTX_DAG_ID='weather_data_pipeline' AIRFLOW_CTX_TASK_ID='compute_averages' AIRFLOW_CTX_EXECUTION_DATE='2024-03-02T21:25:58.120094+00:00' AIRFLOW_CTX_TRY_NUMBER='1' AIRFLOW_CTX_DAG_RUN_ID='manual__2024-03-02T21:25:58.120094+00:00'
[2024-03-03T02:56:03.436+0530] {taskinstance.py:2728} ERROR - Task failed with exception
Traceback (most recent call last):
  File "/Users/anikbhowmick/Python/Big_Data_Assignment/A02/airflow_env/lib/python3.11/site-packages/airflow/models/taskinstance.py", line 444, in _execute_task
    result = _execute_callable(context=context, **execute_callable_kwargs)
             ^^^^^^^^^^^^^^^^^^^^^^^^^^^^^^^^^^^^^^^^^^^^^^^^^^^^^^^^^^^^^
  File "/Users/anikbhowmick/Python/Big_Data_Assignment/A02/airflow_env/lib/python3.11/site-packages/airflow/models/taskinstance.py", line 414, in _execute_callable
    return execute_callable(context=context, **execute_callable_kwargs)
           ^^^^^^^^^^^^^^^^^^^^^^^^^^^^^^^^^^^^^^^^^^^^^^^^^^^^^^^^^^^^
  File "/Users/anikbhowmick/Python/Big_Data_Assignment/A02/airflow_env/lib/python3.11/site-packages/airflow/operators/python.py", line 200, in execute
    return_value = self.execute_callable()
                   ^^^^^^^^^^^^^^^^^^^^^^^
  File "/Users/anikbhowmick/Python/Big_Data_Assignment/A02/airflow_env/lib/python3.11/site-packages/airflow/operators/python.py", line 217, in execute_callable
    return self.python_callable(*self.op_args, **self.op_kwargs)
           ^^^^^^^^^^^^^^^^^^^^^^^^^^^^^^^^^^^^^^^^^^^^^^^^^^^^^
  File "/Users/anikbhowmick/Python/Big_Data_Assignment/A02/airflow_env/airflow/dags/Data_analysis.py", line 72, in compute_monthly_averages
    deserialized_data = pickle.loads(data)
                        ^^^^^^^^^^^^^^^^^^
TypeError: a bytes-like object is required, not 'NoneType'
[2024-03-03T02:56:03.438+0530] {taskinstance.py:1149} INFO - Marking task as UP_FOR_RETRY. dag_id=weather_data_pipeline, task_id=compute_averages, execution_date=20240302T212558, start_date=20240302T212603, end_date=20240302T212603
[2024-03-03T02:56:03.441+0530] {standard_task_runner.py:107} ERROR - Failed to execute job 396 for task compute_averages (a bytes-like object is required, not 'NoneType'; 36663)
[2024-03-03T02:56:03.451+0530] {local_task_job_runner.py:234} INFO - Task exited with return code 1
[2024-03-03T02:56:03.456+0530] {taskinstance.py:3309} INFO - 0 downstream tasks scheduled from follow-on schedule check
