[2024-03-02T15:03:45.441+0530] {taskinstance.py:1979} INFO - Dependencies all met for dep_context=non-requeueable deps ti=<TaskInstance: weather_data_pipeline.wait_for_archive scheduled__2024-02-28T00:06:00+00:00 [queued]>
[2024-03-02T15:03:45.443+0530] {taskinstance.py:1979} INFO - Dependencies all met for dep_context=requeueable deps ti=<TaskInstance: weather_data_pipeline.wait_for_archive scheduled__2024-02-28T00:06:00+00:00 [queued]>
[2024-03-02T15:03:45.443+0530] {taskinstance.py:2193} INFO - Starting attempt 1 of 2
[2024-03-02T15:03:45.447+0530] {taskinstance.py:2214} INFO - Executing <Task(FileSensor): wait_for_archive> on 2024-02-28 00:06:00+00:00
[2024-03-02T15:03:45.449+0530] {standard_task_runner.py:60} INFO - Started process 2539 to run task
[2024-03-02T15:03:45.451+0530] {standard_task_runner.py:87} INFO - Running: ['airflow', 'tasks', 'run', 'weather_data_pipeline', 'wait_for_archive', 'scheduled__2024-02-28T00:06:00+00:00', '--job-id', '154', '--raw', '--subdir', 'DAGS_FOLDER/Data_analysis.py', '--cfg-path', '/var/folders/th/tnjyp6yd1cj78nysn5t4jl6h0000gn/T/tmp31qpr93i']
[2024-03-02T15:03:45.452+0530] {standard_task_runner.py:88} INFO - Job 154: Subtask wait_for_archive
[2024-03-02T15:03:45.468+0530] {task_command.py:423} INFO - Running <TaskInstance: weather_data_pipeline.wait_for_archive scheduled__2024-02-28T00:06:00+00:00 [running]> on host aniks-macbook-air.local
[2024-03-02T15:03:45.485+0530] {taskinstance.py:2510} INFO - Exporting env vars: AIRFLOW_CTX_DAG_OWNER='airflow' AIRFLOW_CTX_DAG_ID='weather_data_pipeline' AIRFLOW_CTX_TASK_ID='wait_for_archive' AIRFLOW_CTX_EXECUTION_DATE='2024-02-28T00:06:00+00:00' AIRFLOW_CTX_TRY_NUMBER='1' AIRFLOW_CTX_DAG_RUN_ID='scheduled__2024-02-28T00:06:00+00:00'
[2024-03-02T15:03:45.488+0530] {base.py:83} INFO - Using connection ID 'fs_default' for task execution.
[2024-03-02T15:03:45.488+0530] {filesystem.py:66} INFO - Poking for file /path/to/archive.zip
[2024-03-02T15:03:46.496+0530] {base.py:83} INFO - Using connection ID 'fs_default' for task execution.
[2024-03-02T15:03:46.497+0530] {filesystem.py:66} INFO - Poking for file /path/to/archive.zip
[2024-03-02T15:03:47.504+0530] {base.py:83} INFO - Using connection ID 'fs_default' for task execution.
[2024-03-02T15:03:47.506+0530] {filesystem.py:66} INFO - Poking for file /path/to/archive.zip
[2024-03-02T15:03:48.512+0530] {base.py:83} INFO - Using connection ID 'fs_default' for task execution.
[2024-03-02T15:03:48.514+0530] {filesystem.py:66} INFO - Poking for file /path/to/archive.zip
[2024-03-02T15:03:49.520+0530] {base.py:83} INFO - Using connection ID 'fs_default' for task execution.
[2024-03-02T15:03:49.521+0530] {filesystem.py:66} INFO - Poking for file /path/to/archive.zip
[2024-03-02T15:03:50.525+0530] {base.py:83} INFO - Using connection ID 'fs_default' for task execution.
[2024-03-02T15:03:50.526+0530] {filesystem.py:66} INFO - Poking for file /path/to/archive.zip
[2024-03-02T15:03:50.527+0530] {taskinstance.py:2728} ERROR - Task failed with exception
Traceback (most recent call last):
  File "/Users/anikbhowmick/Python/Big_Data_Assignment/A02/airflow_env/lib/python3.11/site-packages/airflow/models/taskinstance.py", line 444, in _execute_task
    result = _execute_callable(context=context, **execute_callable_kwargs)
             ^^^^^^^^^^^^^^^^^^^^^^^^^^^^^^^^^^^^^^^^^^^^^^^^^^^^^^^^^^^^^
  File "/Users/anikbhowmick/Python/Big_Data_Assignment/A02/airflow_env/lib/python3.11/site-packages/airflow/models/taskinstance.py", line 414, in _execute_callable
    return execute_callable(context=context, **execute_callable_kwargs)
           ^^^^^^^^^^^^^^^^^^^^^^^^^^^^^^^^^^^^^^^^^^^^^^^^^^^^^^^^^^^^
  File "/Users/anikbhowmick/Python/Big_Data_Assignment/A02/airflow_env/lib/python3.11/site-packages/airflow/sensors/base.py", line 282, in execute
    raise AirflowSensorTimeout(message)
airflow.exceptions.AirflowSensorTimeout: Sensor has timed out; run duration of 5.040790958000798 seconds exceeds the specified timeout of 5.0.
[2024-03-02T15:03:50.532+0530] {taskinstance.py:1149} INFO - Immediate failure requested. Marking task as FAILED. dag_id=weather_data_pipeline, task_id=wait_for_archive, execution_date=20240228T000600, start_date=20240302T093345, end_date=20240302T093350
[2024-03-02T15:03:50.540+0530] {standard_task_runner.py:107} ERROR - Failed to execute job 154 for task wait_for_archive (Sensor has timed out; run duration of 5.040790958000798 seconds exceeds the specified timeout of 5.0.; 2539)
[2024-03-02T15:03:50.550+0530] {local_task_job_runner.py:234} INFO - Task exited with return code 1
[2024-03-02T15:03:50.565+0530] {taskinstance.py:3309} INFO - 0 downstream tasks scheduled from follow-on schedule check
