[2024-03-02T15:12:31.685+0530] {taskinstance.py:1979} INFO - Dependencies all met for dep_context=non-requeueable deps ti=<TaskInstance: weather_data_pipeline.wait_for_archive manual__2024-03-02T09:40:08.685689+00:00 [queued]>
[2024-03-02T15:12:31.687+0530] {taskinstance.py:1979} INFO - Dependencies all met for dep_context=requeueable deps ti=<TaskInstance: weather_data_pipeline.wait_for_archive manual__2024-03-02T09:40:08.685689+00:00 [queued]>
[2024-03-02T15:12:31.688+0530] {taskinstance.py:2193} INFO - Starting attempt 2 of 2
[2024-03-02T15:12:31.691+0530] {taskinstance.py:2214} INFO - Executing <Task(FileSensor): wait_for_archive> on 2024-03-02 09:40:08.685689+00:00
[2024-03-02T15:12:31.694+0530] {standard_task_runner.py:60} INFO - Started process 3042 to run task
[2024-03-02T15:12:31.696+0530] {standard_task_runner.py:87} INFO - Running: ['airflow', 'tasks', 'run', 'weather_data_pipeline', 'wait_for_archive', 'manual__2024-03-02T09:40:08.685689+00:00', '--job-id', '191', '--raw', '--subdir', 'DAGS_FOLDER/Data_analysis.py', '--cfg-path', '/var/folders/th/tnjyp6yd1cj78nysn5t4jl6h0000gn/T/tmp5jqz5ztw']
[2024-03-02T15:12:31.697+0530] {standard_task_runner.py:88} INFO - Job 191: Subtask wait_for_archive
[2024-03-02T15:12:31.711+0530] {task_command.py:423} INFO - Running <TaskInstance: weather_data_pipeline.wait_for_archive manual__2024-03-02T09:40:08.685689+00:00 [running]> on host aniks-macbook-air.local
[2024-03-02T15:12:31.727+0530] {taskinstance.py:2510} INFO - Exporting env vars: AIRFLOW_CTX_DAG_OWNER='airflow' AIRFLOW_CTX_DAG_ID='weather_data_pipeline' AIRFLOW_CTX_TASK_ID='wait_for_archive' AIRFLOW_CTX_EXECUTION_DATE='2024-03-02T09:40:08.685689+00:00' AIRFLOW_CTX_TRY_NUMBER='2' AIRFLOW_CTX_DAG_RUN_ID='manual__2024-03-02T09:40:08.685689+00:00'
[2024-03-02T15:12:31.729+0530] {base.py:83} INFO - Using connection ID 'fs_default' for task execution.
[2024-03-02T15:12:31.730+0530] {filesystem.py:66} INFO - Poking for file /path/to/archive.zip
[2024-03-02T15:12:32.735+0530] {base.py:83} INFO - Using connection ID 'fs_default' for task execution.
[2024-03-02T15:12:32.735+0530] {filesystem.py:66} INFO - Poking for file /path/to/archive.zip
[2024-03-02T15:12:33.742+0530] {base.py:83} INFO - Using connection ID 'fs_default' for task execution.
[2024-03-02T15:12:33.743+0530] {filesystem.py:66} INFO - Poking for file /path/to/archive.zip
[2024-03-02T15:12:34.752+0530] {base.py:83} INFO - Using connection ID 'fs_default' for task execution.
[2024-03-02T15:12:34.754+0530] {filesystem.py:66} INFO - Poking for file /path/to/archive.zip
[2024-03-02T15:12:35.765+0530] {base.py:83} INFO - Using connection ID 'fs_default' for task execution.
[2024-03-02T15:12:35.766+0530] {filesystem.py:66} INFO - Poking for file /path/to/archive.zip
[2024-03-02T15:12:36.773+0530] {base.py:83} INFO - Using connection ID 'fs_default' for task execution.
[2024-03-02T15:12:36.774+0530] {filesystem.py:66} INFO - Poking for file /path/to/archive.zip
[2024-03-02T15:12:37.782+0530] {base.py:83} INFO - Using connection ID 'fs_default' for task execution.
[2024-03-02T15:12:37.784+0530] {filesystem.py:66} INFO - Poking for file /path/to/archive.zip
[2024-03-02T15:12:38.792+0530] {base.py:83} INFO - Using connection ID 'fs_default' for task execution.
[2024-03-02T15:12:38.794+0530] {filesystem.py:66} INFO - Poking for file /path/to/archive.zip
[2024-03-02T15:12:39.803+0530] {base.py:83} INFO - Using connection ID 'fs_default' for task execution.
[2024-03-02T15:12:39.804+0530] {filesystem.py:66} INFO - Poking for file /path/to/archive.zip
[2024-03-02T15:12:40.814+0530] {base.py:83} INFO - Using connection ID 'fs_default' for task execution.
[2024-03-02T15:12:40.815+0530] {filesystem.py:66} INFO - Poking for file /path/to/archive.zip
[2024-03-02T15:12:41.824+0530] {base.py:83} INFO - Using connection ID 'fs_default' for task execution.
[2024-03-02T15:12:41.825+0530] {filesystem.py:66} INFO - Poking for file /path/to/archive.zip
[2024-03-02T15:12:41.827+0530] {taskinstance.py:2728} ERROR - Task failed with exception
Traceback (most recent call last):
  File "/Users/anikbhowmick/Python/Big_Data_Assignment/A02/airflow_env/lib/python3.11/site-packages/airflow/models/taskinstance.py", line 444, in _execute_task
    result = _execute_callable(context=context, **execute_callable_kwargs)
             ^^^^^^^^^^^^^^^^^^^^^^^^^^^^^^^^^^^^^^^^^^^^^^^^^^^^^^^^^^^^^
  File "/Users/anikbhowmick/Python/Big_Data_Assignment/A02/airflow_env/lib/python3.11/site-packages/airflow/models/taskinstance.py", line 414, in _execute_callable
    return execute_callable(context=context, **execute_callable_kwargs)
           ^^^^^^^^^^^^^^^^^^^^^^^^^^^^^^^^^^^^^^^^^^^^^^^^^^^^^^^^^^^^
  File "/Users/anikbhowmick/Python/Big_Data_Assignment/A02/airflow_env/lib/python3.11/site-packages/airflow/sensors/base.py", line 282, in execute
    raise AirflowSensorTimeout(message)
airflow.exceptions.AirflowSensorTimeout: Sensor has timed out; run duration of 10.098012042000846 seconds exceeds the specified timeout of 10.0.
[2024-03-02T15:12:41.834+0530] {taskinstance.py:1149} INFO - Immediate failure requested. Marking task as FAILED. dag_id=weather_data_pipeline, task_id=wait_for_archive, execution_date=20240302T094008, start_date=20240302T094231, end_date=20240302T094241
[2024-03-02T15:12:41.844+0530] {standard_task_runner.py:107} ERROR - Failed to execute job 191 for task wait_for_archive (Sensor has timed out; run duration of 10.098012042000846 seconds exceeds the specified timeout of 10.0.; 3042)
[2024-03-02T15:12:41.873+0530] {local_task_job_runner.py:234} INFO - Task exited with return code 1
[2024-03-02T15:12:41.895+0530] {taskinstance.py:3309} INFO - 0 downstream tasks scheduled from follow-on schedule check
