[2024-03-02T15:05:01.979+0530] {taskinstance.py:1979} INFO - Dependencies all met for dep_context=non-requeueable deps ti=<TaskInstance: weather_data_pipeline.wait_for_archive scheduled__2024-02-28T00:16:00+00:00 [queued]>
[2024-03-02T15:05:01.981+0530] {taskinstance.py:1979} INFO - Dependencies all met for dep_context=requeueable deps ti=<TaskInstance: weather_data_pipeline.wait_for_archive scheduled__2024-02-28T00:16:00+00:00 [queued]>
[2024-03-02T15:05:01.981+0530] {taskinstance.py:2193} INFO - Starting attempt 1 of 2
[2024-03-02T15:05:01.984+0530] {taskinstance.py:2214} INFO - Executing <Task(FileSensor): wait_for_archive> on 2024-02-28 00:16:00+00:00
[2024-03-02T15:05:01.986+0530] {standard_task_runner.py:60} INFO - Started process 2608 to run task
[2024-03-02T15:05:01.989+0530] {standard_task_runner.py:87} INFO - Running: ['airflow', 'tasks', 'run', 'weather_data_pipeline', 'wait_for_archive', 'scheduled__2024-02-28T00:16:00+00:00', '--job-id', '164', '--raw', '--subdir', 'DAGS_FOLDER/Data_analysis.py', '--cfg-path', '/var/folders/th/tnjyp6yd1cj78nysn5t4jl6h0000gn/T/tmpmxqg71aa']
[2024-03-02T15:05:01.989+0530] {standard_task_runner.py:88} INFO - Job 164: Subtask wait_for_archive
[2024-03-02T15:05:02.002+0530] {task_command.py:423} INFO - Running <TaskInstance: weather_data_pipeline.wait_for_archive scheduled__2024-02-28T00:16:00+00:00 [running]> on host aniks-macbook-air.local
[2024-03-02T15:05:02.018+0530] {taskinstance.py:2510} INFO - Exporting env vars: AIRFLOW_CTX_DAG_OWNER='airflow' AIRFLOW_CTX_DAG_ID='weather_data_pipeline' AIRFLOW_CTX_TASK_ID='wait_for_archive' AIRFLOW_CTX_EXECUTION_DATE='2024-02-28T00:16:00+00:00' AIRFLOW_CTX_TRY_NUMBER='1' AIRFLOW_CTX_DAG_RUN_ID='scheduled__2024-02-28T00:16:00+00:00'
[2024-03-02T15:05:02.020+0530] {base.py:83} INFO - Using connection ID 'fs_default' for task execution.
[2024-03-02T15:05:02.020+0530] {filesystem.py:66} INFO - Poking for file /path/to/archive.zip
[2024-03-02T15:05:03.028+0530] {base.py:83} INFO - Using connection ID 'fs_default' for task execution.
[2024-03-02T15:05:03.029+0530] {filesystem.py:66} INFO - Poking for file /path/to/archive.zip
[2024-03-02T15:05:04.035+0530] {base.py:83} INFO - Using connection ID 'fs_default' for task execution.
[2024-03-02T15:05:04.036+0530] {filesystem.py:66} INFO - Poking for file /path/to/archive.zip
[2024-03-02T15:05:05.041+0530] {base.py:83} INFO - Using connection ID 'fs_default' for task execution.
[2024-03-02T15:05:05.041+0530] {filesystem.py:66} INFO - Poking for file /path/to/archive.zip
[2024-03-02T15:05:06.047+0530] {base.py:83} INFO - Using connection ID 'fs_default' for task execution.
[2024-03-02T15:05:06.048+0530] {filesystem.py:66} INFO - Poking for file /path/to/archive.zip
[2024-03-02T15:05:07.053+0530] {base.py:83} INFO - Using connection ID 'fs_default' for task execution.
[2024-03-02T15:05:07.054+0530] {filesystem.py:66} INFO - Poking for file /path/to/archive.zip
[2024-03-02T15:05:07.055+0530] {taskinstance.py:2728} ERROR - Task failed with exception
Traceback (most recent call last):
  File "/Users/anikbhowmick/Python/Big_Data_Assignment/A02/airflow_env/lib/python3.11/site-packages/airflow/models/taskinstance.py", line 444, in _execute_task
    result = _execute_callable(context=context, **execute_callable_kwargs)
             ^^^^^^^^^^^^^^^^^^^^^^^^^^^^^^^^^^^^^^^^^^^^^^^^^^^^^^^^^^^^^
  File "/Users/anikbhowmick/Python/Big_Data_Assignment/A02/airflow_env/lib/python3.11/site-packages/airflow/models/taskinstance.py", line 414, in _execute_callable
    return execute_callable(context=context, **execute_callable_kwargs)
           ^^^^^^^^^^^^^^^^^^^^^^^^^^^^^^^^^^^^^^^^^^^^^^^^^^^^^^^^^^^^
  File "/Users/anikbhowmick/Python/Big_Data_Assignment/A02/airflow_env/lib/python3.11/site-packages/airflow/sensors/base.py", line 282, in execute
    raise AirflowSensorTimeout(message)
airflow.exceptions.AirflowSensorTimeout: Sensor has timed out; run duration of 5.035946749998402 seconds exceeds the specified timeout of 5.0.
[2024-03-02T15:05:07.063+0530] {taskinstance.py:1149} INFO - Immediate failure requested. Marking task as FAILED. dag_id=weather_data_pipeline, task_id=wait_for_archive, execution_date=20240228T001600, start_date=20240302T093501, end_date=20240302T093507
[2024-03-02T15:05:07.072+0530] {standard_task_runner.py:107} ERROR - Failed to execute job 164 for task wait_for_archive (Sensor has timed out; run duration of 5.035946749998402 seconds exceeds the specified timeout of 5.0.; 2608)
[2024-03-02T15:05:07.079+0530] {local_task_job_runner.py:234} INFO - Task exited with return code 1
[2024-03-02T15:05:07.093+0530] {taskinstance.py:3309} INFO - 0 downstream tasks scheduled from follow-on schedule check
