[2024-03-02T15:12:20.443+0530] {taskinstance.py:1979} INFO - Dependencies all met for dep_context=non-requeueable deps ti=<TaskInstance: weather_data_pipeline.wait_for_archive scheduled__2024-03-01T00:33:00+00:00 [queued]>
[2024-03-02T15:12:20.445+0530] {taskinstance.py:1979} INFO - Dependencies all met for dep_context=requeueable deps ti=<TaskInstance: weather_data_pipeline.wait_for_archive scheduled__2024-03-01T00:33:00+00:00 [queued]>
[2024-03-02T15:12:20.445+0530] {taskinstance.py:2193} INFO - Starting attempt 1 of 2
[2024-03-02T15:12:20.450+0530] {taskinstance.py:2214} INFO - Executing <Task(FileSensor): wait_for_archive> on 2024-03-01 00:33:00+00:00
[2024-03-02T15:12:20.452+0530] {standard_task_runner.py:60} INFO - Started process 3031 to run task
[2024-03-02T15:12:20.454+0530] {standard_task_runner.py:87} INFO - Running: ['airflow', 'tasks', 'run', 'weather_data_pipeline', 'wait_for_archive', 'scheduled__2024-03-01T00:33:00+00:00', '--job-id', '190', '--raw', '--subdir', 'DAGS_FOLDER/Data_analysis.py', '--cfg-path', '/var/folders/th/tnjyp6yd1cj78nysn5t4jl6h0000gn/T/tmp3291xu3x']
[2024-03-02T15:12:20.455+0530] {standard_task_runner.py:88} INFO - Job 190: Subtask wait_for_archive
[2024-03-02T15:12:20.468+0530] {task_command.py:423} INFO - Running <TaskInstance: weather_data_pipeline.wait_for_archive scheduled__2024-03-01T00:33:00+00:00 [running]> on host aniks-macbook-air.local
[2024-03-02T15:12:20.485+0530] {taskinstance.py:2510} INFO - Exporting env vars: AIRFLOW_CTX_DAG_OWNER='airflow' AIRFLOW_CTX_DAG_ID='weather_data_pipeline' AIRFLOW_CTX_TASK_ID='wait_for_archive' AIRFLOW_CTX_EXECUTION_DATE='2024-03-01T00:33:00+00:00' AIRFLOW_CTX_TRY_NUMBER='1' AIRFLOW_CTX_DAG_RUN_ID='scheduled__2024-03-01T00:33:00+00:00'
[2024-03-02T15:12:20.487+0530] {base.py:83} INFO - Using connection ID 'fs_default' for task execution.
[2024-03-02T15:12:20.488+0530] {filesystem.py:66} INFO - Poking for file /path/to/archive.zip
[2024-03-02T15:12:21.495+0530] {base.py:83} INFO - Using connection ID 'fs_default' for task execution.
[2024-03-02T15:12:21.496+0530] {filesystem.py:66} INFO - Poking for file /path/to/archive.zip
[2024-03-02T15:12:22.503+0530] {base.py:83} INFO - Using connection ID 'fs_default' for task execution.
[2024-03-02T15:12:22.504+0530] {filesystem.py:66} INFO - Poking for file /path/to/archive.zip
[2024-03-02T15:12:23.512+0530] {base.py:83} INFO - Using connection ID 'fs_default' for task execution.
[2024-03-02T15:12:23.514+0530] {filesystem.py:66} INFO - Poking for file /path/to/archive.zip
[2024-03-02T15:12:24.523+0530] {base.py:83} INFO - Using connection ID 'fs_default' for task execution.
[2024-03-02T15:12:24.524+0530] {filesystem.py:66} INFO - Poking for file /path/to/archive.zip
[2024-03-02T15:12:25.530+0530] {base.py:83} INFO - Using connection ID 'fs_default' for task execution.
[2024-03-02T15:12:25.531+0530] {filesystem.py:66} INFO - Poking for file /path/to/archive.zip
[2024-03-02T15:12:26.537+0530] {base.py:83} INFO - Using connection ID 'fs_default' for task execution.
[2024-03-02T15:12:26.538+0530] {filesystem.py:66} INFO - Poking for file /path/to/archive.zip
[2024-03-02T15:12:27.552+0530] {base.py:83} INFO - Using connection ID 'fs_default' for task execution.
[2024-03-02T15:12:27.553+0530] {filesystem.py:66} INFO - Poking for file /path/to/archive.zip
[2024-03-02T15:12:28.561+0530] {base.py:83} INFO - Using connection ID 'fs_default' for task execution.
[2024-03-02T15:12:28.562+0530] {filesystem.py:66} INFO - Poking for file /path/to/archive.zip
[2024-03-02T15:12:29.568+0530] {base.py:83} INFO - Using connection ID 'fs_default' for task execution.
[2024-03-02T15:12:29.569+0530] {filesystem.py:66} INFO - Poking for file /path/to/archive.zip
[2024-03-02T15:12:30.572+0530] {base.py:83} INFO - Using connection ID 'fs_default' for task execution.
[2024-03-02T15:12:30.572+0530] {filesystem.py:66} INFO - Poking for file /path/to/archive.zip
[2024-03-02T15:12:30.573+0530] {taskinstance.py:2728} ERROR - Task failed with exception
Traceback (most recent call last):
  File "/Users/anikbhowmick/Python/Big_Data_Assignment/A02/airflow_env/lib/python3.11/site-packages/airflow/models/taskinstance.py", line 444, in _execute_task
    result = _execute_callable(context=context, **execute_callable_kwargs)
             ^^^^^^^^^^^^^^^^^^^^^^^^^^^^^^^^^^^^^^^^^^^^^^^^^^^^^^^^^^^^^
  File "/Users/anikbhowmick/Python/Big_Data_Assignment/A02/airflow_env/lib/python3.11/site-packages/airflow/models/taskinstance.py", line 414, in _execute_callable
    return execute_callable(context=context, **execute_callable_kwargs)
           ^^^^^^^^^^^^^^^^^^^^^^^^^^^^^^^^^^^^^^^^^^^^^^^^^^^^^^^^^^^^
  File "/Users/anikbhowmick/Python/Big_Data_Assignment/A02/airflow_env/lib/python3.11/site-packages/airflow/sensors/base.py", line 282, in execute
    raise AirflowSensorTimeout(message)
airflow.exceptions.AirflowSensorTimeout: Sensor has timed out; run duration of 10.086558208999122 seconds exceeds the specified timeout of 10.0.
[2024-03-02T15:12:30.576+0530] {taskinstance.py:1149} INFO - Immediate failure requested. Marking task as FAILED. dag_id=weather_data_pipeline, task_id=wait_for_archive, execution_date=20240301T003300, start_date=20240302T094220, end_date=20240302T094230
[2024-03-02T15:12:30.581+0530] {standard_task_runner.py:107} ERROR - Failed to execute job 190 for task wait_for_archive (Sensor has timed out; run duration of 10.086558208999122 seconds exceeds the specified timeout of 10.0.; 3031)
[2024-03-02T15:12:30.609+0530] {local_task_job_runner.py:234} INFO - Task exited with return code 1
[2024-03-02T15:12:30.619+0530] {taskinstance.py:3309} INFO - 0 downstream tasks scheduled from follow-on schedule check
