[2024-03-08T13:11:58.081+0530] {taskinstance.py:1979} INFO - Dependencies all met for dep_context=non-requeueable deps ti=<TaskInstance: weather_data_pipeline.Comb_data_loc manual__2024-03-08T07:37:32.149992+00:00 [queued]>
[2024-03-08T13:11:58.083+0530] {taskinstance.py:1979} INFO - Dependencies all met for dep_context=requeueable deps ti=<TaskInstance: weather_data_pipeline.Comb_data_loc manual__2024-03-08T07:37:32.149992+00:00 [queued]>
[2024-03-08T13:11:58.083+0530] {taskinstance.py:2193} INFO - Starting attempt 1 of 2
[2024-03-08T13:11:58.087+0530] {taskinstance.py:2214} INFO - Executing <Task(PythonOperator): Comb_data_loc> on 2024-03-08 07:37:32.149992+00:00
[2024-03-08T13:11:58.091+0530] {standard_task_runner.py:60} INFO - Started process 13940 to run task
[2024-03-08T13:11:58.093+0530] {standard_task_runner.py:87} INFO - Running: ['airflow', 'tasks', 'run', 'weather_data_pipeline', 'Comb_data_loc', 'manual__2024-03-08T07:37:32.149992+00:00', '--job-id', '606', '--raw', '--subdir', 'DAGS_FOLDER/Data_analysis.py', '--cfg-path', '/var/folders/th/tnjyp6yd1cj78nysn5t4jl6h0000gn/T/tmpbnrhiorw']
[2024-03-08T13:11:58.094+0530] {standard_task_runner.py:88} INFO - Job 606: Subtask Comb_data_loc
[2024-03-08T13:11:58.107+0530] {task_command.py:423} INFO - Running <TaskInstance: weather_data_pipeline.Comb_data_loc manual__2024-03-08T07:37:32.149992+00:00 [running]> on host aniks-macbook-air.local
[2024-03-08T13:11:58.124+0530] {taskinstance.py:2510} INFO - Exporting env vars: AIRFLOW_CTX_DAG_OWNER='airflow' AIRFLOW_CTX_DAG_ID='weather_data_pipeline' AIRFLOW_CTX_TASK_ID='Comb_data_loc' AIRFLOW_CTX_EXECUTION_DATE='2024-03-08T07:37:32.149992+00:00' AIRFLOW_CTX_TRY_NUMBER='1' AIRFLOW_CTX_DAG_RUN_ID='manual__2024-03-08T07:37:32.149992+00:00'
[2024-03-08T13:11:58.124+0530] {taskinstance.py:2728} ERROR - Task failed with exception
Traceback (most recent call last):
  File "/Users/anikbhowmick/Python/Big_Data_Assignment/A02/airflow_env/lib/python3.11/site-packages/airflow/models/taskinstance.py", line 444, in _execute_task
    result = _execute_callable(context=context, **execute_callable_kwargs)
             ^^^^^^^^^^^^^^^^^^^^^^^^^^^^^^^^^^^^^^^^^^^^^^^^^^^^^^^^^^^^^
  File "/Users/anikbhowmick/Python/Big_Data_Assignment/A02/airflow_env/lib/python3.11/site-packages/airflow/models/taskinstance.py", line 414, in _execute_callable
    return execute_callable(context=context, **execute_callable_kwargs)
           ^^^^^^^^^^^^^^^^^^^^^^^^^^^^^^^^^^^^^^^^^^^^^^^^^^^^^^^^^^^^
  File "/Users/anikbhowmick/Python/Big_Data_Assignment/A02/airflow_env/lib/python3.11/site-packages/airflow/operators/python.py", line 200, in execute
    return_value = self.execute_callable()
                   ^^^^^^^^^^^^^^^^^^^^^^^
  File "/Users/anikbhowmick/Python/Big_Data_Assignment/A02/airflow_env/lib/python3.11/site-packages/airflow/operators/python.py", line 217, in execute_callable
    return self.python_callable(*self.op_args, **self.op_kwargs)
           ^^^^^^^^^^^^^^^^^^^^^^^^^^^^^^^^^^^^^^^^^^^^^^^^^^^^^
  File "/Users/anikbhowmick/Python/Big_Data_Assignment/A02/airflow_env/airflow/dags/Data_analysis.py", line 97, in combine_data
    files=os.listdir(file_path)
          ^^^^^^^^^^^^^^^^^^^^^
FileNotFoundError: [Errno 2] No such file or directory: '/Users/anikbhowmick/Python/Big_Data_Assignment/A02/airflow_env/Data_storage/2023_data/'
[2024-03-08T13:11:58.127+0530] {taskinstance.py:1149} INFO - Marking task as UP_FOR_RETRY. dag_id=weather_data_pipeline, task_id=Comb_data_loc, execution_date=20240308T073732, start_date=20240308T074158, end_date=20240308T074158
[2024-03-08T13:11:58.129+0530] {standard_task_runner.py:107} ERROR - Failed to execute job 606 for task Comb_data_loc ([Errno 2] No such file or directory: '/Users/anikbhowmick/Python/Big_Data_Assignment/A02/airflow_env/Data_storage/2023_data/'; 13940)
[2024-03-08T13:11:58.155+0530] {local_task_job_runner.py:234} INFO - Task exited with return code 1
[2024-03-08T13:11:58.160+0530] {taskinstance.py:3309} INFO - 0 downstream tasks scheduled from follow-on schedule check
